Workbook

Sheet Instructions
B1: DAS Sentinel — User Acceptance Test (UAT) Script
B3: 1. What you are testing
B4: DAS Sentinel is an AI security-testing and automated penetration-testing platform for AUTHORIZED defensive assessments. A tester creates an engagement, defines its scope, accepts the Rules of Engagement (ROE), adds targets, runs scanners / AI-LLM test suites against in-scope targets, triages the resulting findings (CVSS + compliance mapping), and exports compliance-ready reports. This UAT verifies every user-facing function, the API-only features that have no screen yet, the safety controls that block unauthorized testing, and the security of the platform itself.
B5: How to use this workbook: work top-to-bottom through each module tab. For every row, perform the 'Test Steps' exactly, compare what you see against 'Expected Result', then set the 'Status' cell (dropdown) to Pass / Fail / Blocked / N/A. Record anything unexpected under 'Actual Result / Notes' with your initials and the date. Raise a row on the 'Defects' tab for every Fail and put its Defect ID back in the notes cell. The 'Summary' tab tallies everything automatically.
B6: Rows whose Expected Result begins with KNOWN GAP describe behaviour that is currently correct-as-built but incomplete. Mark them Pass when you observe exactly what is described, and record the observation — they are the shipping-readiness list, not defects. Rows marked OBSERVED BEHAVIOUR TO CONFIRM are decisions for the product owner: record what happens, do not judge it.
B8: 2. Status values (the checkbox)
B9: Pass | C9: The system behaved exactly as the Expected Result describes.
B10: Fail | C10: Behaviour differed from Expected Result. Always fill in Actual Result / Notes and raise a Defects row.
B11: Blocked | C11: Could not run the test (dependency / earlier failure / environment down).
B12: N/A | C12: Not applicable to this environment or role, or the feature has no path to exercise it (the row says so).
B13: Not Run | C13: Default — not yet executed.
B15: 3. Environment & access
B16: Application URL | C16: https://localhost (served by the Caddy reverse proxy). In dev the TLS certificate is self-signed — accept the browser warning once. Your admin may give a different hostname.
B17: Browser | C17: Latest Chrome, Edge, or Firefox. Use a clean profile / private window so no old session cookie interferes. You will need DevTools for AUTH-16 and SEC-01.
B18: Start the stack | C18: From the repo root: cp .env.example .env (fill values) → docker compose up -d . The 'migrate' service applies the database schema automatically before 'api' starts. Wait until 'docker compose ps' shows api / web / proxy / postgres / valkey healthy.
B19: Seed the first login | C19: The platform ships with no users. Create the first admin by running the seed script inside the compose network: docker compose run --rm --no-deps -v "$PWD/apps/api/scripts:/app/scripts:ro" --entrypoint sh api -c "cd /app && PYTHONPATH=/app uv run --no-sync python scripts/seed_e2e_user.py"
B20: Session timeouts | C20: Sessions are 15-minute sliding idle and 8-hour absolute. If you pause mid-module for more than 15 minutes you WILL be signed out and land on /login?expired=1 — that is correct behaviour (AUTH-15), not a defect.
B21: API calls | C21: Several rows are API-only. Authenticate the same way the browser does (session cookie) and send the X-CSRF-Token header on every POST / PATCH / DELETE — the token is returned in the login response body and set as a cookie. A cookie without the header is rejected by design (SEC-01).
B23: 4. Test accounts (create these before the RBAC tests)
B24: Log in as the seeded admin, open Administration > Users, and create one account per role. IMPORTANT: you do NOT choose a password. The form takes Email, Display name and Role only; the platform generates a ONE-TIME temporary password and shows it once in a green panel — copy it before clicking Done. Each new user's first login lands on /set-password and must set a permanent password of 12+ characters that is not in the common-breach list (so 'Password1234!' is refused). Record the permanent passwords you set somewhere safe.
B25: Admin (seeded) | C25: e2e-admin@dassentinel.example.com / e2e horse battery staple (role: Admin) — this one has a known password and no forced change.
B26: Tester | C26: tester@dassentinel.example.com — temp password from the panel, then you set a permanent one (role: Tester)
B27: Reviewer | C27: reviewer@dassentinel.example.com — same flow (role: Reviewer). Reviewer is also the role that APPROVES high-risk gates.
B28: Read-only | C28: readonly@dassentinel.example.com — same flow (role: Read only)
B29: Throwaway | C29: throwaway@dassentinel.example.com — create a FIFTH account purely for the destructive rows (USR-07 deactivate, ACCT-09 email change). Deactivation cannot be undone from the product (USR-13), so never spend one of the four role accounts on it.
B31: 5. Roles & what each can do (RBAC quick reference)
B32: Admin | C32: Everything: user management, credentials, engagements, scope, ROE, targets, scans, approving high-risk gates, validation, reports, audit log.
B33: Tester | C33: Manage engagements / scope / ROE / targets, launch & cancel scans, REQUEST high-risk gates, validate findings, credentials, reports. NO user management, NO audit log, and CANNOT approve a high-risk gate.
B34: Reviewer | C34: View everything, APPROVE / deny / revoke high-risk gates, validate findings (CVSS + compliance), export reports, view audit log. CANNOT create engagements, launch scans, request gates, or touch credentials.
B35: Read only | C35: View-only across engagements, scope, ROE, targets, scans, findings, reports, AI models and health. Cannot change anything, cannot export reports, and has no access to credentials, users or the audit log. Caveat to confirm: the SARIF export route is VIEW-gated, so this role can still pull every finding as SARIF (FND-10).
B36: Everyone | C36: Every signed-in role has its own account settings (/profile): change name, email, phone and password.
B37: Enforcement | C37: Sidebar items are hidden by role for convenience, but the API is the real enforcement — a forbidden action returns 403 with a role message even if reached directly by URL. Capability table: apps/api/app/core/deps.py.
B39: 6. Suggested end-to-end run order
B40: 1) Authentication → 2) Account & Profile → 3) Navigation & Dashboard → 4) Engagements → 5) Scope → 6) ROE → 7) Targets → 8) Source Archive → 9) Scans → 10) Safety & Scope Enforcement → 11) Approvals → 12) Findings → 13) CVSS → 14) Compliance → 15) Evidence → 16) Reports → 17) Credentials → 18) Users → 19) Audit Log → 20) AI Models → 21) Health → 22) Platform Security → 23) Agent Permission → 24) API-Only Features.
B41: Ordering notes: tab 18 (Users) creates the accounts that tabs 1 and 2 need, so on a first pass do USR-01…USR-02 early, then come back. Modules 4–16 build on each other — do them in order the first time through. Tabs 22 and 23 are mostly scripted and can run in parallel with the UI work.
B43: 7. Running the live verification scripts
B44: Tabs 11, 22, 23 and several API-only rows call the shipped live-verification scripts in apps/api/scripts/. They are the same proofs used for the go-live gates: each drives the real API / database / object store and exits 0 on success, non-zero with a message on failure. The standard invocation is:
B45: docker compose run --rm --no-deps -v "$PWD/apps/api/scripts:/app/scripts:ro" --entrypoint sh api -c "cd /app && PYTHONPATH=/app uv run --no-sync [--with httpx] python scripts/<script>.py"
B46: Each row gives the exact command including any extra mounts (sandbox, compliance KB) or the --with httpx flag. Record the exit status and paste any failure output into Actual Result / Notes. A few scripts need a specific image (scanners / redteam) — their own docstring says so.
B48: 8. Known gaps to confirm (not defects unless behaviour differs)
...

Sheet Summary
B1: UAT Results Summary
B2: Counts update automatically as you set Status values on each module tab.
B4: Module | C4: Total | D4: Pass | E4: Fail | F4: Blocked | G4: N/A | H4: Not Run | I4: Pass %
B5: 01. Authentication | C5: =COUNTA('01. Authentication'!$A$5:$A$500) | D5: =COUNTIF('01. Authentication'!$G$5:$G$500,"Pass") | E5: =COUNTIF('01. Authentication'!$G$5:$G$500,"Fail") | F5: =COUNTIF('01. Authentication'!$G$5:$G$500,"Blocked") | G5: =COUNTIF('01. Authentication'!$G$5:$G$500,"N/A") | H5: =COUNTIF('01. Authentication'!$G$5:$G$500,"Not Run") | I5: =IF(SUM(D5+E5)=0,"-",TEXT(D5/(D5+E5),"0%"))
B6: 02. Account & Profile | C6: =COUNTA('02. Account & Profile'!$A$5:$A$500) | D6: =COUNTIF('02. Account & Profile'!$G$5:$G$500,"Pass") | E6: =COUNTIF('02. Account & Profile'!$G$5:$G$500,"Fail") | F6: =COUNTIF('02. Account & Profile'!$G$5:$G$500,"Blocked") | G6: =COUNTIF('02. Account & Profile'!$G$5:$G$500,"N/A") | H6: =COUNTIF('02. Account & Profile'!$G$5:$G$500,"Not Run") | I6: =IF(SUM(D6+E6)=0,"-",TEXT(D6/(D6+E6),"0%"))
B7: 03. Navigation | C7: =COUNTA('03. Navigation'!$A$5:$A$500) | D7: =COUNTIF('03. Navigation'!$G$5:$G$500,"Pass") | E7: =COUNTIF('03. Navigation'!$G$5:$G$500,"Fail") | F7: =COUNTIF('03. Navigation'!$G$5:$G$500,"Blocked") | G7: =COUNTIF('03. Navigation'!$G$5:$G$500,"N/A") | H7: =COUNTIF('03. Navigation'!$G$5:$G$500,"Not Run") | I7: =IF(SUM(D7+E7)=0,"-",TEXT(D7/(D7+E7),"0%"))
B8: 04. Engagements | C8: =COUNTA('04. Engagements'!$A$5:$A$500) | D8: =COUNTIF('04. Engagements'!$G$5:$G$500,"Pass") | E8: =COUNTIF('04. Engagements'!$G$5:$G$500,"Fail") | F8: =COUNTIF('04. Engagements'!$G$5:$G$500,"Blocked") | G8: =COUNTIF('04. Engagements'!$G$5:$G$500,"N/A") | H8: =COUNTIF('04. Engagements'!$G$5:$G$500,"Not Run") | I8: =IF(SUM(D8+E8)=0,"-",TEXT(D8/(D8+E8),"0%"))
B9: 05. Scope | C9: =COUNTA('05. Scope'!$A$5:$A$500) | D9: =COUNTIF('05. Scope'!$G$5:$G$500,"Pass") | E9: =COUNTIF('05. Scope'!$G$5:$G$500,"Fail") | F9: =COUNTIF('05. Scope'!$G$5:$G$500,"Blocked") | G9: =COUNTIF('05. Scope'!$G$5:$G$500,"N/A") | H9: =COUNTIF('05. Scope'!$G$5:$G$500,"Not Run") | I9: =IF(SUM(D9+E9)=0,"-",TEXT(D9/(D9+E9),"0%"))
B10: 06. ROE | C10: =COUNTA('06. ROE'!$A$5:$A$500) | D10: =COUNTIF('06. ROE'!$G$5:$G$500,"Pass") | E10: =COUNTIF('06. ROE'!$G$5:$G$500,"Fail") | F10: =COUNTIF('06. ROE'!$G$5:$G$500,"Blocked") | G10: =COUNTIF('06. ROE'!$G$5:$G$500,"N/A") | H10: =COUNTIF('06. ROE'!$G$5:$G$500,"Not Run") | I10: =IF(SUM(D10+E10)=0,"-",TEXT(D10/(D10+E10),"0%"))
B11: 07. Targets | C11: =COUNTA('07. Targets'!$A$5:$A$500) | D11: =COUNTIF('07. Targets'!$G$5:$G$500,"Pass") | E11: =COUNTIF('07. Targets'!$G$5:$G$500,"Fail") | F11: =COUNTIF('07. Targets'!$G$5:$G$500,"Blocked") | G11: =COUNTIF('07. Targets'!$G$5:$G$500,"N/A") | H11: =COUNTIF('07. Targets'!$G$5:$G$500,"Not Run") | I11: =IF(SUM(D11+E11)=0,"-",TEXT(D11/(D11+E11),"0%"))
B12: 08. Source Archive | C12: =COUNTA('08. Source Archive'!$A$5:$A$500) | D12: =COUNTIF('08. Source Archive'!$G$5:$G$500,"Pass") | E12: =COUNTIF('08. Source Archive'!$G$5:$G$500,"Fail") | F12: =COUNTIF('08. Source Archive'!$G$5:$G$500,"Blocked") | G12: =COUNTIF('08. Source Archive'!$G$5:$G$500,"N/A") | H12: =COUNTIF('08. Source Archive'!$G$5:$G$500,"Not Run") | I12: =IF(SUM(D12+E12)=0,"-",TEXT(D12/(D12+E12),"0%"))
B13: 09. Scans | C13: =COUNTA('09. Scans'!$A$5:$A$500) | D13: =COUNTIF('09. Scans'!$G$5:$G$500,"Pass") | E13: =COUNTIF('09. Scans'!$G$5:$G$500,"Fail") | F13: =COUNTIF('09. Scans'!$G$5:$G$500,"Blocked") | G13: =COUNTIF('09. Scans'!$G$5:$G$500,"N/A") | H13: =COUNTIF('09. Scans'!$G$5:$G$500,"Not Run") | I13: =IF(SUM(D13+E13)=0,"-",TEXT(D13/(D13+E13),"0%"))
B14: 10. Safety | C14: =COUNTA('10. Safety'!$A$5:$A$500) | D14: =COUNTIF('10. Safety'!$G$5:$G$500,"Pass") | E14: =COUNTIF('10. Safety'!$G$5:$G$500,"Fail") | F14: =COUNTIF('10. Safety'!$G$5:$G$500,"Blocked") | G14: =COUNTIF('10. Safety'!$G$5:$G$500,"N/A") | H14: =COUNTIF('10. Safety'!$G$5:$G$500,"Not Run") | I14: =IF(SUM(D14+E14)=0,"-",TEXT(D14/(D14+E14),"0%"))
B15: 11. Approvals | C15: =COUNTA('11. Approvals'!$A$5:$A$500) | D15: =COUNTIF('11. Approvals'!$G$5:$G$500,"Pass") | E15: =COUNTIF('11. Approvals'!$G$5:$G$500,"Fail") | F15: =COUNTIF('11. Approvals'!$G$5:$G$500,"Blocked") | G15: =COUNTIF('11. Approvals'!$G$5:$G$500,"N/A") | H15: =COUNTIF('11. Approvals'!$G$5:$G$500,"Not Run") | I15: =IF(SUM(D15+E15)=0,"-",TEXT(D15/(D15+E15),"0%"))
B16: 12. Findings | C16: =COUNTA('12. Findings'!$A$5:$A$500) | D16: =COUNTIF('12. Findings'!$G$5:$G$500,"Pass") | E16: =COUNTIF('12. Findings'!$G$5:$G$500,"Fail") | F16: =COUNTIF('12. Findings'!$G$5:$G$500,"Blocked") | G16: =COUNTIF('12. Findings'!$G$5:$G$500,"N/A") | H16: =COUNTIF('12. Findings'!$G$5:$G$500,"Not Run") | I16: =IF(SUM(D16+E16)=0,"-",TEXT(D16/(D16+E16),"0%"))
B17: 13. CVSS | C17: =COUNTA('13. CVSS'!$A$5:$A$500) | D17: =COUNTIF('13. CVSS'!$G$5:$G$500,"Pass") | E17: =COUNTIF('13. CVSS'!$G$5:$G$500,"Fail") | F17: =COUNTIF('13. CVSS'!$G$5:$G$500,"Blocked") | G17: =COUNTIF('13. CVSS'!$G$5:$G$500,"N/A") | H17: =COUNTIF('13. CVSS'!$G$5:$G$500,"Not Run") | I17: =IF(SUM(D17+E17)=0,"-",TEXT(D17/(D17+E17),"0%"))
B18: 14. Compliance | C18: =COUNTA('14. Compliance'!$A$5:$A$500) | D18: =COUNTIF('14. Compliance'!$G$5:$G$500,"Pass") | E18: =COUNTIF('14. Compliance'!$G$5:$G$500,"Fail") | F18: =COUNTIF('14. Compliance'!$G$5:$G$500,"Blocked") | G18: =COUNTIF('14. Compliance'!$G$5:$G$500,"N/A") | H18: =COUNTIF('14. Compliance'!$G$5:$G$500,"Not Run") | I18: =IF(SUM(D18+E18)=0,"-",TEXT(D18/(D18+E18),"0%"))
B19: 15. Evidence | C19: =COUNTA('15. Evidence'!$A$5:$A$500) | D19: =COUNTIF('15. Evidence'!$G$5:$G$500,"Pass") | E19: =COUNTIF('15. Evidence'!$G$5:$G$500,"Fail") | F19: =COUNTIF('15. Evidence'!$G$5:$G$500,"Blocked") | G19: =COUNTIF('15. Evidence'!$G$5:$G$500,"N/A") | H19: =COUNTIF('15. Evidence'!$G$5:$G$500,"Not Run") | I19: =IF(SUM(D19+E19)=0,"-",TEXT(D19/(D19+E19),"0%"))
B20: 16. Reports | C20: =COUNTA('16. Reports'!$A$5:$A$500) | D20: =COUNTIF('16. Reports'!$G$5:$G$500,"Pass") | E20: =COUNTIF('16. Reports'!$G$5:$G$500,"Fail") | F20: =COUNTIF('16. Reports'!$G$5:$G$500,"Blocked") | G20: =COUNTIF('16. Reports'!$G$5:$G$500,"N/A") | H20: =COUNTIF('16. Reports'!$G$5:$G$500,"Not Run") | I20: =IF(SUM(D20+E20)=0,"-",TEXT(D20/(D20+E20),"0%"))
B21: 17. Credentials | C21: =COUNTA('17. Credentials'!$A$5:$A$500) | D21: =COUNTIF('17. Credentials'!$G$5:$G$500,"Pass") | E21: =COUNTIF('17. Credentials'!$G$5:$G$500,"Fail") | F21: =COUNTIF('17. Credentials'!$G$5:$G$500,"Blocked") | G21: =COUNTIF('17. Credentials'!$G$5:$G$500,"N/A") | H21: =COUNTIF('17. Credentials'!$G$5:$G$500,"Not Run") | I21: =IF(SUM(D21+E21)=0,"-",TEXT(D21/(D21+E21),"0%"))
B22: 18. Users | C22: =COUNTA('18. Users'!$A$5:$A$500) | D22: =COUNTIF('18. Users'!$G$5:$G$500,"Pass") | E22: =COUNTIF('18. Users'!$G$5:$G$500,"Fail") | F22: =COUNTIF('18. Users'!$G$5:$G$500,"Blocked") | G22: =COUNTIF('18. Users'!$G$5:$G$500,"N/A") | H22: =COUNTIF('18. Users'!$G$5:$G$500,"Not Run") | I22: =IF(SUM(D22+E22)=0,"-",TEXT(D22/(D22+E22),"0%"))
B23: 19. Audit Log | C23: =COUNTA('19. Audit Log'!$A$5:$A$500) | D23: =COUNTIF('19. Audit Log'!$G$5:$G$500,"Pass") | E23: =COUNTIF('19. Audit Log'!$G$5:$G$500,"Fail") | F23: =COUNTIF('19. Audit Log'!$G$5:$G$500,"Blocked") | G23: =COUNTIF('19. Audit Log'!$G$5:$G$500,"N/A") | H23: =COUNTIF('19. Audit Log'!$G$5:$G$500,"Not Run") | I23: =IF(SUM(D23+E23)=0,"-",TEXT(D23/(D23+E23),"0%"))
B24: 20. AI Models | C24: =COUNTA('20. AI Models'!$A$5:$A$500) | D24: =COUNTIF('20. AI Models'!$G$5:$G$500,"Pass") | E24: =COUNTIF('20. AI Models'!$G$5:$G$500,"Fail") | F24: =COUNTIF('20. AI Models'!$G$5:$G$500,"Blocked") | G24: =COUNTIF('20. AI Models'!$G$5:$G$500,"N/A") | H24: =COUNTIF('20. AI Models'!$G$5:$G$500,"Not Run") | I24: =IF(SUM(D24+E24)=0,"-",TEXT(D24/(D24+E24),"0%"))
B25: 21. Health | C25: =COUNTA('21. Health'!$A$5:$A$500) | D25: =COUNTIF('21. Health'!$G$5:$G$500,"Pass") | E25: =COUNTIF('21. Health'!$G$5:$G$500,"Fail") | F25: =COUNTIF('21. Health'!$G$5:$G$500,"Blocked") | G25: =COUNTIF('21. Health'!$G$5:$G$500,"N/A") | H25: =COUNTIF('21. Health'!$G$5:$G$500,"Not Run") | I25: =IF(SUM(D25+E25)=0,"-",TEXT(D25/(D25+E25),"0%"))
B26: 22. Platform Security | C26: =COUNTA('22. Platform Security'!$A$5:$A$500) | D26: =COUNTIF('22. Platform Security'!$G$5:$G$500,"Pass") | E26: =COUNTIF('22. Platform Security'!$G$5:$G$500,"Fail") | F26: =COUNTIF('22. Platform Security'!$G$5:$G$500,"Blocked") | G26: =COUNTIF('22. Platform Security'!$G$5:$G$500,"N/A") | H26: =COUNTIF('22. Platform Security'!$G$5:$G$500,"Not Run") | I26: =IF(SUM(D26+E26)=0,"-",TEXT(D26/(D26+E26),"0%"))
B27: 23. Agent Permission | C27: =COUNTA('23. Agent Permission'!$A$5:$A$500) | D27: =COUNTIF('23. Agent Permission'!$G$5:$G$500,"Pass") | E27: =COUNTIF('23. Agent Permission'!$G$5:$G$500,"Fail") | F27: =COUNTIF('23. Agent Permission'!$G$5:$G$500,"Blocked") | G27: =COUNTIF('23. Agent Permission'!$G$5:$G$500,"N/A") | H27: =COUNTIF('23. Agent Permission'!$G$5:$G$500,"Not Run") | I27: =IF(SUM(D27+E27)=0,"-",TEXT(D27/(D27+E27),"0%"))
B28: 24. API-Only | C28: =COUNTA('24. API-Only'!$A$5:$A$500) | D28: =COUNTIF('24. API-Only'!$G$5:$G$500,"Pass") | E28: =COUNTIF('24. API-Only'!$G$5:$G$500,"Fail") | F28: =COUNTIF('24. API-Only'!$G$5:$G$500,"Blocked") | G28: =COUNTIF('24. API-Only'!$G$5:$G$500,"N/A") | H28: =COUNTIF('24. API-Only'!$G$5:$G$500,"Not Run") | I28: =IF(SUM(D28+E28)=0,"-",TEXT(D28/(D28+E28),"0%"))
B29: TOTAL | C29: =SUM(C5:C28) | D29: =SUM(D5:D28) | E29: =SUM(E5:E28) | F29: =SUM(F5:F28) | G29: =SUM(G5:G28) | H29: =SUM(H5:H28) | I29: =IF(SUM(D29+E29)=0,"-",TEXT(D29/(D29+E29),"0%"))
B31: Defects raised | C31: =COUNTA(Defects!$A$5:$A$64) | D31: =COUNTIF(Defects!$C$5:$C$64,"Critical") | E31: =COUNTIF(Defects!$C$5:$C$64,"High")
B32: (total · critical · high)
B34: Sign-off
B35: Tester name:
B36: Role:
B37: Build / commit under test:
B38: Date started:
B39: Date completed:
B40: Overall result (Accept / Reject):
B41: Notes:

Sheet 01. Authentication
A1: Authentication & Session Management
A2: Login, logout, session persistence, revocation, and login-security controls.
A4: Test ID | B4: Test Case | C4: Preconditions | D4: Test Steps (perform in order) | E4: Test Data | F4: Expected Result | G4: Status | H4: Actual Result / Notes | I4: Tested By | J4: Date
A5: AUTH-01 | B5: Login page renders | C5: App is running; you are logged out. | D5: 1. In a clean browser window go to https://localhost. 2. If not already there, you are redirected to /login. 3. Observe the page. | E5: URL: https://localhost | F5: Browser tab title 'Sign in — DAS Sentinel'. Centred shield logo, H1 'DAS Sentinel', subtext 'AI-based Automated Security Testing'. Fields: Email, Password. Button 'Sign in'. Footer line 'DAS Sentinel · authorized defensive assessments only'. | G5: Pass | H5: RE-RUN 2026-08-03 on 0ded8a1 + UAT fixes (incl. forced-change enforcement). https://localhost redirected to https://localhost/login; title 'Sign in — DAS Sentinel'; H1 ['DAS Sentinel']; labels ['Email', 'Password']; buttons ['Sign in']; footer present=True Evidence: docs/uat-evidence/01-authentication/ | I5: Claude Code (Playwright, headed Chromium) | J5: 2026-08-03
A6: AUTH-02 | B6: Valid login (admin) | C6: Seeded admin exists. | D6: 1. Enter the admin email and password. 2. Click 'Sign in'. 3. Observe the button text and where you land. 4. Look at the top-right of the header. | E6: e2e-admin@dassentinel.example.com / e2e horse battery staple | F6: Button briefly shows 'Signing in…'. On success the whole app reloads and you land on the Dashboard (/). A round initials avatar appears at the top-right of the header (identity lives there, NOT in the sidebar). | G6: Pass | H6: RE-RUN 2026-08-03 on 0ded8a1 + UAT fixes (incl. forced-change enforcement). button labels seen ['Signing in…']; landed https://localhost/ H1 'Dashboard'; header avatar 'EA' Evidence: docs/uat-evidence/01-authentication/ | I6: Claude Code (Playwright, headed Chromium) | J6: 2026-08-03
A7: AUTH-03 | B7: Wrong password rejected | C7: On /login, logged out. | D7: 1. Enter a valid email but the wrong password. 2. Click 'Sign in'. | E7: admin email + 'wrongpassword' | F7: Red inline alert: 'Invalid email or password.' You remain on /login. Button re-enables. | G7: Pass | H7: RE-RUN 2026-08-03 on 0ded8a1 + UAT fixes (incl. forced-change enforcement). alert ['Invalid email or password.']; stayed on https://localhost/login; button re-enabled=True Evidence: docs/uat-evidence/01-authentication/ | I7: Claude Code (Playwright, headed Chromium) | J7: 2026-08-03
A8: AUTH-04 | B8: Unknown email — no user enumeration | C8: On /login. | D8: 1. Enter an email that has no account and any password. 2. Click 'Sign in'. | E8: nobody@example.com / anything | F8: Same generic 'Invalid email or password.' message as AUTH-03 (the app must NOT reveal whether the email exists). | G8: Pass | H8: RE-RUN 2026-08-03 on 0ded8a1 + UAT fixes (incl. forced-change enforcement). unknown email gave the identical alert ['Invalid email or password.'] on https://localhost/login — no enumeration signal Evidence: docs/uat-evidence/01-authentication/ | I8: Claude Code (Playwright, headed Chromium) | J8: 2026-08-03
A9: AUTH-05 | B9: Empty submit | C9: On /login. | D9: 1. Leave Email and Password blank. 2. Click 'Sign in'. | E9: (empty) | F9: The form submits (native validation is suppressed) and returns the generic invalid-credentials error; no crash. | G9: Pass | H9: RE-RUN 2026-08-03 on 0ded8a1 + UAT fixes (incl. forced-change enforcement). empty submit -> alert ['Invalid email or password.'] on https://localhost/login; no crash (API 422 is now mapped to the generic message) Evidence: docs/uat-evidence/01-authentication/ | I9: Claude Code (Playwright, headed Chromium) | J9: 2026-08-03
A10: AUTH-06 | B10: Deactivated account cannot log in | C10: A user was deactivated (see USR-08). | D10: 1. Attempt to log in with the deactivated user's correct credentials. | E10: deactivated user creds | F10: Login fails with the same generic 'Invalid email or password.' (deactivated accounts are indistinguishable from wrong credentials). | G10: Pass | H10: RE-RUN 2026-08-03 on 0ded8a1 + UAT fixes (incl. forced-change enforcement). credentials verified working first (True); after deactivation the same correct credentials gave ['Invalid email or password.'] on https://localhost/login — indistinguishable from a wrong password Evidence: docs/uat-evidence/01-authentication/ | I10: Claude Code (Playwright, headed Chromium) | J10: 2026-08-03
A11: AUTH-07 | B11: Login rate limiting | C11: On /login. | D11: 1. Pick a burnt / non-role account (never one of the four role accounts — a failed run leaves the per-IP counter running). 2. Submit wrong credentials for that same email 6 times in a row. 3. Watch the response status in DevTools > Network as well as the on-screen message. | E11: 6 wrong logins on one email. Limits: 5 failures per email and 30 per IP, both in a 15-minute rolling window (login_rate_limit_* settings). | F11: After the threshold, further attempts are throttled (server returns 429) and the UI shows 'Sign-in failed — the API is unreachable. Try again.' (every non-401 maps to that branch). Waiting clears it. Scripted proof: verify_login_ratelimit.py — see tab '22. Platform Security'. | G11: Pass | H11: RE-RUN 2026-08-03 on 0ded8a1 + UAT fixes (incl. forced-change enforcement). status sequence [401, 401, 401, 401, 429] — throttled at attempt 5 (per-email limit is 5, per-IP 30); UI showed ['Sign-in failed — the API is unreachable. Try again.'] Evidence: docs/uat-evidence/01-authentication/ | I11: Claude Code (Playwright, headed Chromium) | J11: 2026-08-03
A12: AUTH-08 | B12: Session persists | C12: Logged in as admin. | D12: 1. Navigate to several pages. 2. Refresh the browser (F5). 3. Open a new tab to https://localhost. | E12: - | F12: You stay logged in across navigation, refresh and new tabs — no re-login prompt. The user menu still shows your identity. | G12: Pass | H12: RE-RUN 2026-08-03 on 0ded8a1 + UAT fixes (incl. forced-change enforcement). navigation [('/engagements', '/engagements', 'EA'), ('/health', '/health', 'EA'), ('/users', '/users', 'EA')]; after F5 ('/users', True); new tab ('/', 'EA') — signed in throughout, no re-login Evidence: docs/uat-evidence/01-authentication/ | I12: Claude Code (Playwright, headed Chromium) | J12: 2026-08-03
A13: AUTH-09 | B13: Expired / revoked banner | C13: Logged out. | D13: 1. Browse to https://localhost/login?expired=1 . | E13: /login?expired=1 | F13: An amber banner appears: 'Your session has expired or was revoked. Sign in again.' | G13: Pass | H13: RE-RUN 2026-08-03 on 0ded8a1 + UAT fixes (incl. forced-change enforcement). /login?expired=1 shows the amber banner: True Evidence: docs/uat-evidence/01-authentication/ | I13: Claude Code (Playwright, headed Chromium) | J13: 2026-08-03
A14: AUTH-10 | B14: Account menu identity | C14: Logged in. | D14: 1. Click the round initials avatar at the top-right of the header. 2. Read the panel that opens. | E14: - | F14: The avatar shows your initials. The panel shows display name (bold), email (muted) and a role Badge matching your role (Admin / Tester / Reviewer / Read only), then 'Account settings', 'Sign out' and 'Sign out everywhere'. NOTE: there is no user block at the bottom of the sidebar. | G14: Pass | H14: RE-RUN 2026-08-03 on 0ded8a1 + UAT fixes (incl. forced-change enforcement). avatar 'EA'; menu = E2E Admin | | e2e-admin@dassentinel.example.com | | Admin | Account settings | Sign out | Sign out everywhere; sidebar contains no user block Evidence: docs/uat-evidence/01-authentication/ | I14: Claude Code (Playwright, headed Chromium) | J14: 2026-08-03
A15: AUTH-11 | B15: Sign out | C15: Logged in. | D15: 1. Open the account menu (initials avatar, top-right). 2. Click 'Sign out'. | E15: - | F15: You are redirected to /login and your session is revoked. Pressing Back does not restore an authenticated page (you get redirected to login). | G15: Pass | H15: RE-RUN 2026-08-03 on 0ded8a1 + UAT fixes (incl. forced-change enforcement). sign out -> https://localhost/login, cookies cleared ([]); Back -> https://localhost/login (no authenticated page restored) Evidence: docs/uat-evidence/01-authentication/ | I15: Claude Code (Playwright, headed Chromium) | J15: 2026-08-03
... A21: AUTH-17 | B21: Revocation is immediate, not cached | C21: Two browsers signed in as the SAME non-admin user; an admin available. | D21: 1. In browser A stay on a page. 2. As admin, change that user's role (or deactivate them). 3. In browser A refresh or navigate. | E21: - | F21: Browser A is bounced to /login?expired=1 on its very next request — the revocation clears both the Valkey session cache AND the DB row, so there is no stale-cache window. Scripted proof: verify_rbac.py (SEC-06). | G21: Pass | H21: RE-RUN 2026-08-03 on 0ded8a1 + UAT fixes (incl. forced-change enforcement). tester was on ('/engagements', 'UT'); after the admin changed the role it was bounced on the very next request — refresh -> /login?expired=1 (expired banner=True); in-app nav -> /login?expired=1 (expired banner=True). No stale-cache window. Evidence: docs/uat-evidence/01-authentication/ | I21: Claude Code (Playwright, headed Chromium) | J21: 2026-08-03

Sheet 02. Account & Profile
A1: Account & Profile (self-service)
A2: First-login password setup, self-service profile and password change. Every signed-in role has these — they are reached from the account menu (initials avatar, top-right), not the sidebar.
A4: Test ID | B4: Test Case | C4: Preconditions | D4: Test Steps (perform in order) | E4: Test Data | F4: Expected Result | G4: Status | H4: Actual Result / Notes | I4: Tested By | J4: Date
A5: ACCT-01 | B5: Forced password change on first login | C5: A user created by an admin (USR-02) plus its one-time temporary password. | D5: 1. Sign out. 2. Sign in with the new user's email and its temporary password. 3. Observe where you land. | E5: new user + temp password | F5: The login itself succeeds and you are sent to /set-password — NOT the Dashboard. H1 'Set your password', subtext 'You signed in with a temporary password. Choose a permanent one to continue.' Fields: New password, Confirm password. Button 'Set password'. The page has no sidebar or account menu. (How binding that redirect is: see ACCT-14.) | G5: Pass | H5: RE-RUN 2026-08-03 on 0ded8a1 + UAT fixes (incl. forced-change enforcement). landed https://localhost/set-password (not the Dashboard); H1 ['Set your password']; labels ['New password', 'Confirm password']; buttons ['Set password']; sidebar elements=0, header elements=0 — no app chrome Evidence: docs/uat-evidence/02-account-profile/ | I5: Claude Code (Playwright, headed Chromium) | J5: 2026-08-03
A6: ACCT-02 | B6: Minimum length enforced | C6: On /set-password. | D6: 1. Enter 'shortpass' in both fields. 2. Click 'Set password'. | E6: shortpass (9 chars) | F6: Blocked client-side with 'Password must be at least 12 characters.' No request is sent; you stay on /set-password. | G6: Pass | H6: RE-RUN 2026-08-03 on 0ded8a1 + UAT fixes (incl. forced-change enforcement). alert ['Password must be at least 12 characters.']; API calls made: none; stayed on https://localhost/set-password Evidence: docs/uat-evidence/02-account-profile/ | I6: Claude Code (Playwright, headed Chromium) | J6: 2026-08-03
A7: ACCT-03 | B7: Confirmation must match | C7: On /set-password. | D7: 1. Enter a valid 12+ character password. 2. Enter something different in Confirm password. 3. Click 'Set password'. | E7: two different 12+ char values | F7: Blocked with 'Passwords do not match.' Nothing is saved. | G7: Pass | H7: RE-RUN 2026-08-03 on 0ded8a1 + UAT fixes (incl. forced-change enforcement). alert ['Passwords do not match.']; API calls made: none — nothing saved Evidence: docs/uat-evidence/02-account-profile/ | I7: Claude Code (Playwright, headed Chromium) | J7: 2026-08-03
A8: ACCT-04 | B8: Breached / common password refused | C8: On /set-password. | D8: 1. Enter a well-known breached password of 12+ characters in both fields. 2. Click 'Set password'. | E8: Password1234! | F8: Rejected (422) and the API's own message is surfaced: 'password appears in a known-breach/common-password list; choose another'. This is the check that USR-04 can no longer perform (the create-user form has no password field). Scripted proof: verify_password_breach.py (SEC-08). | G8: Pass | H8: RE-RUN 2026-08-03 on 0ded8a1 + UAT fixes (incl. forced-change enforcement). alert ['password appears in a known-breach/common-password list; choose another']; request ['POST /api/auth/me/password'] (API 422, message surfaced verbatim) Evidence: docs/uat-evidence/02-account-profile/ | I8: Claude Code (Playwright, headed Chromium) | J8: 2026-08-03
A9: ACCT-05 | B9: Set a valid permanent password | C9: On /set-password. | D9: 1. Enter the same strong 12+ character password in both fields. 2. Click 'Set password'. 3. Sign out, sign in with the NEW password. 4. Sign out, try the OLD temporary password. | E9: your chosen 12+ char password | F9: Button shows 'Saving…', then you land on the Dashboard (/) with the session still valid (no second login needed). The new password works; the temporary one is dead ('Invalid email or password.'), and you are never sent to /set-password again. | G9: Pass | H9: RE-RUN 2026-08-03 on 0ded8a1 + UAT fixes (incl. forced-change enforcement). button labels ['Saving…']; landed https://localhost/ still signed in=True; must_change_password now False; new password logs in ok=True; temporary password now gives ['Invalid email or password.'] Evidence: docs/uat-evidence/02-account-profile/ | I9: Claude Code (Playwright, headed Chromium) | J9: 2026-08-03
A10: ACCT-06 | B10: Account settings page opens | C10: Logged in as any role. | D10: 1. Click the initials avatar (top-right). 2. Click 'Account settings'. | E10: - | F10: You land on /profile — title 'Account settings', subtext 'Update your profile and password. Changes are attributed and audited.' Two cards: 'Profile' (Name, Email, Phone number) and 'Password' (Current, New, Confirm). Available to EVERY role, including Read only. | G10: Pass | H10: RE-RUN 2026-08-03 on 0ded8a1 + UAT fixes (incl. forced-change enforcement). account menu -> https://localhost/profile; H1 ['Account settings']; Profile + Password cards with fields ['Name', 'Email', 'Phone number', 'Current password', 'New password', 'Confirm new password'] Evidence: docs/uat-evidence/02-account-profile/ | I10: Claude Code (Playwright, headed Chromium) | J10: 2026-08-03
A11: ACCT-07 | B11: Change display name | C11: On /profile. | D11: 1. Change Name. 2. Click 'Save profile'. 3. Reopen the account menu. | E11: 'UAT Tester Two' | F11: Green 'Profile saved.' The account-menu name and the avatar initials both reflect the new name (the page refreshes its server data). | G11: Pass | H11: RE-RUN 2026-08-03 on 0ded8a1 + UAT fixes (incl. forced-change enforcement). ['Profile saved.']; account menu now shows UAT Acct Two | | uat-r3-acct@dassentinel.example.com | | Tester | Account settings | Sign out | Sign out everywhere; avatar 'UA'; request body [('PATCH', '/api/auth/me', '{"display_name":"UAT Acct Two"}')] Evidence: docs/uat-evidence/02-account-profile/ | I11: Claude Code (Playwright, headed Chromium) | J11: 2026-08-03
A12: ACCT-08 | B12: Phone number is optional | C12: On /profile. | D12: 1. Enter a phone number and save. 2. Clear the field and save again. | E12: +1 555 0100 / (blank) | F12: Both saves succeed ('Profile saved.'). A blank phone is stored as empty (null), not rejected. Only the fields you actually changed are sent (PATCH). | G12: Pass | H12: RE-RUN 2026-08-03 on 0ded8a1 + UAT fixes (incl. forced-change enforcement). both saves succeeded [('set', ['Profile saved.']), ('cleared', ['Profile saved.'])]; cleared phone stored as None (null); PATCH bodies now carry only the changed field: [['{"phone":"+1 555 0100"}'], ['{"phone":null}']] Evidence: docs/uat-evidence/02-account-profile/ | I12: Claude Code (Playwright, headed Chromium) | J12: 2026-08-03
A13: ACCT-09 | B13: Change own email | C13: On /profile, as a throwaway (non-admin) account. | D13: 1. Change Email to a new unused address. 2. Click 'Save profile'. 3. Sign out and sign in with the NEW email. | E13: tester2@dassentinel.example.com | F13: 'Profile saved.' The account menu shows the new email, and login now requires it — the old address no longer authenticates. Do NOT do this on the seeded admin unless you record the new address. | G13: Pass | H13: RE-RUN 2026-08-03 on 0ded8a1 + UAT fixes (incl. forced-change enforcement). PATCH returned [('PATCH', '/api/auth/me', 200)] in 4.0s (was an indefinite hang before the fix); ['Profile saved.']; account menu shows the new address (True); signing in with the new address works=True; the old address now gives ['Invalid email or password.'] Evidence: docs/uat-evidence/02-account-profile/ | I13: Claude Code (Playwright, headed Chromium) | J13: 2026-08-03
A14: ACCT-10 | B14: Duplicate email refused | C14: Two users exist. | D14: 1. On /profile change your Email to another existing user's address. 2. Click 'Save profile'. | E14: an email already in use | F14: Rejected (409): 'That email is already in use.' Your email is unchanged. | G14: Pass | H14: RE-RUN 2026-08-03 on 0ded8a1 + UAT fixes (incl. forced-change enforcement). HTTP [('PATCH', '/api/auth/me', 409)]; message ['That email is already in use.']; my email unchanged (uat-r3-acct@dassentinel.example.com) Evidence: docs/uat-evidence/02-account-profile/ | I14: Claude Code (Playwright, headed Chromium) | J14: 2026-08-03
A15: ACCT-11 | B15: Change own password — all failure paths | C15: On /profile, Password card. | D15: 1. Wrong Current password + a valid new password → save. 2. Correct current + new under 12 chars → save. 3. Correct current + mismatched confirm → save. 4. Correct current + a breached 12+ password → save. 5. Correct current + a good new password → save. | E15: see steps | F15: In order: (1) 400 → 'Current password is incorrect.'; (2) 'New password must be at least 12 characters.'; (3) 'New passwords do not match.'; (4) 422 → the known-breach message; (5) green 'Password changed.' and all three fields clear. The new password works on the next login. | G15: Pass | H15: RE-RUN 2026-08-03 on 0ded8a1 + UAT fixes (incl. forced-change enforcement). in order: [('1-wrong-current', [400], ['Current password is incorrect.']), ('2-too-short', [], ['New password must be at least 12 characters.']), ('3-mismatch', [], ['New passwords do not match.']), ('4-breached', [422], ['password appears in a known-breach/common-password list; choose another']), ('5-success', [200], ['Password changed.'])]; fields cleared after success (['', '', '']); new password works on the next login=True Evidence: docs/uat-evidence/02-account-profile/ | I15: Claude Code (Playwright, headed Chromium) | J15: 2026-08-03
... A18: ACCT-14 | B18: Forced password change is binding | C18: Signed in with a temporary password and sitting on /set-password (ACCT-01). Do NOT set a password yet. | D18: 1. Without setting a password, type https://localhost/ in the address bar. 2. Try to reach a feature page directly, e.g. https://localhost/engagements. 3. With the same session, call the API: GET /api/auth/me (read the must_change_password flag), then GET and POST /api/engagements. 4. Now set a permanent password and repeat step 2. | E18: - | F18: The forced change is ENFORCED, in the UI and in the API. Every page bounces back to /set-password while must_change_password is true. On the API, GET /api/auth/me still works (the app needs your identity) and POST /api/auth/me/password and the logout routes are allowed, but every other endpoint returns 403 {"detail":{"code":"password_change_required"}} — enforced centrally in get_principal (apps/api/app/core/deps.py), not per-route. After a permanent password is set the same session is released immediately and the app works normally. A shared temporary password therefore cannot be used as a working account. | G18: Pass | H18: RE-RUN 2026-08-03 on 0ded8a1 + UAT fixes (incl. forced-change enforcement). ENFORCED. With must_change_password=True: typing https://localhost/ in the address bar bounced to /set-password ['Set your password']; /engagements bounced to /set-password ['Set your password']; on the same session GET /api/engagements returned 403 and POST /api/engagements returned 403 {"detail":{"code":"password_change_required"}} — both refused by the shared get_principal dependency, not just hidden in the UI. Release is verified in ACCT-05. Evidence: docs/uat-evidence/02-account-profile/ | I18: Claude Code (Playwright, headed Chromium) | J18: 2026-08-03

Sheet 03. Navigation
A1: Navigation & Dashboard
A2: Sidebar, dashboard, contextual engagement nav, and layout behaviour.
A4: Test ID | B4: Test Case | C4: Preconditions | D4: Test Steps (perform in order) | E4: Test Data | F4: Expected Result | G4: Status | H4: Actual Result / Notes | I4: Tested By | J4: Date
A5: NAV-01 | B5: Dashboard loads | C5: Logged in. | D5: 1. Go to https://localhost/ (or click the logo). | E5: - | F5: Page shows H1 'Dashboard' with subtext about evidence-backed findings, and an 'M0 — foundation' card containing a 'system health' link. | G5: Pass | H5: H1 'Dashboard'; subtext 'Evidence-backed, compliance-mapped findings from authorized security testing.'; 'M0 — foundation' card present=True; 'system health' link inside it=True Evidence: docs/uat-evidence/03-navigation/ | I5: Claude Code (Playwright, headed Chromium) | J5: 2026-08-03
A6: NAV-02 | B6: Sidebar sections (admin) | C6: Logged in as admin. | D6: 1. Read the left sidebar top to bottom. | E6: - | F6: Sections in order: Overview (Dashboard) · Testing (Engagements) · Credentials (Credentials) · Administration (Users) · Output (Audit log) · System (AI models, Health). | G6: Pass | H6: sidebar sections in order: [('OVERVIEW', ['Dashboard']), ('TESTING', ['Engagements']), ('CREDENTIALS', ['Credentials']), ('ADMINISTRATION', ['Users']), ('OUTPUT', ['Audit log']), ('SYSTEM', ['AI models', 'Health'])] Evidence: docs/uat-evidence/03-navigation/ | I6: Claude Code (Playwright, headed Chromium) | J6: 2026-08-03
A7: NAV-03 | B7: Health link from dashboard | C7: On Dashboard. | D7: 1. Click the 'system health' link inside the foundation card. | E7: - | F7: You navigate to the /health page. | G7: Pass | H7: clicking 'system health' navigated to https://localhost/health (H1 'System health') Evidence: docs/uat-evidence/03-navigation/ | I7: Claude Code (Playwright, headed Chromium) | J7: 2026-08-03
A8: NAV-04 | B8: Logo returns to Dashboard | C8: Any page. | D8: 1. Click the 'DAS Sentinel' logo at the top of the sidebar. | E8: - | F8: You return to the Dashboard (/). Subtext under the logo reads 'Authorized testing only'. | G8: Pass | H8: logo reads 'DAS Sentinel / Authorized testing only'; clicking it from /health returned to https://localhost/ Evidence: docs/uat-evidence/03-navigation/ | I8: Claude Code (Playwright, headed Chromium) | J8: 2026-08-03
A9: NAV-05 | B9: Contextual engagement nav | C9: At least one engagement exists. | D9: 1. Open any engagement (/engagements/{id}). 2. Look at the sidebar. | E9: - | F9: A 'Current engagement' section appears with: Overview, Targets, Scans, Findings, Reports. Targets/Scans are hash anchors that scroll the overview; Findings/Reports open their own pages. | G9: Pass | H9: 'CURRENT ENGAGEMENT' section present with Overview/Targets/Scans/Findings/Reports; links {'Overview': '/engagements/83492ed3-1389-4fd5-bb39-2a16dccc8fd1', 'Targets': '/engagements/83492ed3-1389-4fd5-bb39-2a16dccc8fd1#targets', 'Scans': '/engagements/83492ed3-1389-4fd5-bb39-2a16dccc8fd1#scans', 'Findings': '/engagements/83492ed3-1389-4fd5-bb39-2a16dccc8fd1/findings', 'Reports': '/engagements/83492ed3-1389-4fd5-bb39-2a16dccc8fd1/reports'}. Behaviour verified: Targets scrolled the overview to y=1513 at /engagements/83492ed3-1389-4fd5-bb39-2a16dccc8fd1#targets, Scans to y=1583 at /engagements/83492ed3-1389-4fd5-bb39-2a16dccc8fd1#scans, Findings opened its own page ('/engagements/83492ed3-1389-4fd5-bb39-2a16dccc8fd1/findings', 'Findings'), Reports opened ('/engagements/83492ed3-1389-4fd5-bb39-2a16dccc8fd1/reports', 'Reports') The contextual section also persists across the engagement sub-pages (/findings, /reports) and disappears outside the engagement, with the active item highlighted correctly. Evidence: docs/uat-evidence/03-navigation/ | I9: Claude Code (Playwright, headed Chromium) | J9: 2026-08-03
A10: NAV-06 | B10: Sidebar stays visible | C10: A long page (e.g. an engagement with many items). | D10: 1. Scroll the main content down. | E10: - | F10: The sidebar navigation stays fixed/sticky and visible while the content scrolls. | G10: Pass | H10: page has 9336px of scroll; scrolled to y=4000; sidebar box {'x': 0, 'y': 0, 'width': 256, 'height': 850} -> {'x': 0, 'y': 0, 'width': 256, 'height': 850}; logo y 20 -> 20 (unmoved); nav links still visible=True Evidence: docs/uat-evidence/03-navigation/ | I10: Claude Code (Playwright, headed Chromium) | J10: 2026-08-03
A11: NAV-07 | B11: Engagement context bar | C11: Inside an engagement. | D11: 1. Observe the top of any page under an engagement. | E11: - | F11: A breadcrumb 'Engagements / {name}' plus the engagement status badge is shown. Admin/Reviewer also see a 'View audit log' link scoped to that engagement. | G11: Pass | H11: top of the engagement page: 'EA\nEngagements / e2e-roe-revert-1785498573274\nDraft\nView audit log\ne2e-roe-revert-1785498573274\nEdit\nDetails\nClient / system'; first links [('Engagements', '/engagements'), ('e2e-roe-revert-1785498573274', '/engagements/83492ed3-1389-4fd5-bb39-2a16dccc8fd1'), ('View audit log', '/audit?engagement=83492ed3-1389-4fd5-bb39-2a16dccc8fd1'), ('Edit', '/engagements/83492ed3-1389-4fd5-bb39-2a16dccc8fd1/edit'), ('Add target', '/engagements/83492ed3-1389-4fd5-bb39-2a16dccc8fd1/targets/new'), ('Add LLM target', '/engagements/83492ed3-1389-4fd5-bb39-2a16dccc8fd1/targets/new')]; 'View audit log' present=True href=/audit?engagement=83492ed3-1389-4fd5-bb39-2a16dccc8fd1 Role gating also checked: signed in as a Tester the same page shows the breadcrumb and status badge but NO 'View audit log' link (0 matches), and the sidebar correctly drops the Administration and Output sections. Evidence: docs/uat-evidence/03-navigation/ | I11: Claude Code (Playwright, headed Chromium) | J11: 2026-08-03

Sheet 04. Engagements
A1: Engagements (CRUD & Lifecycle)
A2: Create, edit, list, status transitions, and delete engagements.
A4: Test ID | B4: Test Case | C4: Preconditions | D4: Test Steps (perform in order) | E4: Test Data | F4: Expected Result | G4: Status | H4: Actual Result / Notes | I4: Tested By | J4: Date
A5: ENG-01 | B5: Engagements list & empty state | C5: Logged in as admin/tester. | D5: 1. Click Testing > Engagements. | E5: - | F5: Page H1 'Engagements'. If none exist, a dashed 'No engagements yet…' box shows. A 'New engagement' button is top-right. | G5: Pass | H5: H1 'Engagements'; 'New engagement' button top-right of the heading; 240 engagements listed so the dashed 'No engagements yet…' box is correctly absent (False) — that branch needs an empty org Role check: the 'New engagement' button is correctly absent for Reviewer and Read only (0 matches each) after the DEF-009 fix. Evidence: docs/uat-evidence/04-engagements/ | I5: Claude Code (Playwright, headed Chromium) | J5: 2026-08-03
A6: ENG-02 | B6: Create engagement | C6: On /engagements. | D6: 1. Click 'New engagement'. 2. Fill Name and Client / system. 3. Set a test window start & end, rate limit, max intensity, contacts. 4. Click 'Create engagement'. | E6: Name: 'UAT Web App' Client: 'ACME Portal' Window: today→+7 days Rate limit: 5 Intensity: Safe active | F6: Button shows 'Saving…', then you land on the new engagement detail page. The engagement is created in 'Draft' status. | G6: Pass | H6: button labels ['Add scope item', 'Saving…']; landed on /engagements/34853da2-870a-48c1-b9e8-941499be75f6; name shown; created in 'Draft' Evidence: docs/uat-evidence/04-engagements/ | I6: Claude Code (Playwright, headed Chromium) | J6: 2026-08-03
A7: ENG-03 | B7: Required fields | C7: On the new-engagement form. | D7: 1. Leave Name and Client / system blank. 2. Click 'Create engagement'. | E7: (empty required fields) | F7: The form blocks submission for the required Name / Client fields (native required). | G7: Pass | H7: native validation is on (noValidate=False); blank submit stayed on https://localhost/engagements/new, made NO API call (none), Name/Client flagged valueMissing (True/True), and no misleading server error appeared (none) Evidence: docs/uat-evidence/04-engagements/ | I7: Claude Code (Playwright, headed Chromium) | J7: 2026-08-03
A8: ENG-04 | B8: Test window end must be after start | C8: On the form. | D8: 1. Set 'Test window end' earlier than or equal to 'Test window start'. 2. Submit. | E8: start: today 15:00 end: today 09:00 | F8: Save fails with inline alert: 'Some fields are invalid — check the test window and rate limit.' (server 422). | G8: Pass | H8: end before start -> HTTP [422]; inline alert ['Some fields are invalid — check the test window and rate limit.']; stayed on /engagements/new Evidence: docs/uat-evidence/04-engagements/ | I8: Claude Code (Playwright, headed Chromium) | J8: 2026-08-03
A9: ENG-05 | B9: Rate limit bounds | C9: On the form. | D9: 1. Try rate limit 0, then 2000, then a valid 5. | E9: 0 / 2000 / 5 | F9: Values below 1 or above 1000 are rejected (number field min=1 max=1000); 5 is accepted. | G9: Pass | H9: min=1 max=1000 default=5; validity {'0': False, '2000': False, '5': True} Evidence: docs/uat-evidence/04-engagements/ | I9: Claude Code (Playwright, headed Chromium) | J9: 2026-08-03
A10: ENG-06 | B10: Max intensity options | C10: On the form. | D10: 1. Open the 'Maximum intensity' dropdown. | E10: - | F10: Exactly four options: Passive, Safe active (default), Authenticated active, High risk. | G10: Pass | H10: exactly 4 options ['Passive', 'Safe active', 'Authenticated active', 'High risk']; default = 'safe_active' (Safe active) Evidence: docs/uat-evidence/04-engagements/ | I10: Claude Code (Playwright, headed Chromium) | J10: 2026-08-03
A11: ENG-07 | B11: Hosted LLMs toggle | C11: On the form. | D11: 1. Note the 'Hosted LLMs allowed (otherwise local models only)' checkbox state, toggle, save. | E11: - | F11: Checkbox defaults to unchecked (local models only). Saved value is reflected on the detail 'Details' card as 'Allowed' or 'Local models only'. | G11: Pass | H11: checkbox defaults unchecked (False); Details card read ['Local models only'] and after ticking + saving reads ['Allowed'] Evidence: docs/uat-evidence/04-engagements/ | I11: Claude Code (Playwright, headed Chromium) | J11: 2026-08-03
A12: ENG-08 | B12: List columns & ordering | C12: ≥2 engagements exist. | D12: 1. Return to /engagements. | E12: - | F12: Table columns: Name (link), Client / system, Status (badge), Max intensity (label), Rate limit (n rps). Newest engagement appears at the top. | G12: Pass | H12: columns (CSS-uppercased) ['NAME', 'CLIENT / SYSTEM', 'STATUS', 'MAX INTENSITY', 'RATE LIMIT']; Name cell is a link to /engagements/59c1031a-eab2-49ea-9030-a550551f29ac; Status shown as a badge and Rate limit as '10 rps'; newest engagement is the top row ['UAT Web App 2 (renamed)', 'ACME Portal', 'Draft'] Evidence: docs/uat-evidence/04-engagements/ | I12: Claude Code (Playwright, headed Chromium) | J12: 2026-08-03
A13: ENG-09 | B13: Detail 'Details' card | C13: On an engagement detail. | D13: 1. Read the 'Details' card. | E13: - | F13: Shows Client/system, both test window datetimes (or '—'), Rate limit (n rps), Maximum intensity, Hosted LLMs, both contacts (or '—'), Created and Updated timestamps. | G13: Pass | H13: Details card carries every field: {'Client / system': True, 'Test window start': True, 'Test window end': True, 'Rate limit': True, 'Maximum intensity': True, 'Hosted LLMs': True, 'Coordination contact': True, 'Emergency-stop contact': True, 'Created': True, 'Updated': True}; rate limit rendered as '5 rps' Evidence: docs/uat-evidence/04-engagements/ | I13: Claude Code (Playwright, headed Chromium) | J13: 2026-08-03
A14: ENG-10 | B14: Edit engagement | C14: On an engagement. | D14: 1. Click 'Edit'. 2. Change the Name and rate limit. 3. Click 'Save changes'. | E14: New name; rate limit 10 | F14: Returns to the detail page with the updated values. Note: status is NOT editable here. | G14: Pass | H14: edit form fields ['name', 'client_system_name', 'test_window_start', 'test_window_end', 'rate_limit_rps', 'max_intensity', 'hosted_models_allowed', 'coordination_contact', 'emergency_stop_contact'] — no status field, so status is not editable here; detail now shows the new name and '10 rps' Evidence: docs/uat-evidence/04-engagements/ | I14: Claude Code (Playwright, headed Chromium) | J14: 2026-08-03
A15: ENG-11 | B15: Status transitions | C15: A Draft engagement. | D15: 1. In the Status card, click 'Activate' (Draft→Active). 2. Click 'Pause' (Active→Paused). 3. Click 'Activate' (Paused→Active). 4. Click 'Close' and confirm 'Close this engagement? Closed is terminal.'. | E15: - | F15: Each transition succeeds and the status badge updates. Only valid transitions offer buttons. After Close, the card reads 'Closed is terminal — no further transitions.' | G15: Pass | H15: Activate: Draft->Active HTTP [200]; Pause: Active->Paused HTTP [200]; Activate: Paused->Active HTTP [200]; Close dialog ['Close this engagement? Closed is terminal.']; cancelling left it Active; confirming gave Closed Evidence: docs/uat-evidence/04-engagements/ | I15: Claude Code (Playwright, headed Chromium) | J15: 2026-08-03
... A18: ENG-14 | B18: RBAC — read-only/reviewer cannot modify | C18: Logged in as Reviewer, then Read-only. | D18: 1. Open an engagement. 2. Attempt Edit / status change / delete (or open /engagements/{id}/edit by URL and save). | E18: reviewer & read_only accounts | F18: Mutations are refused with a role message, e.g. 'Your role can view engagements but not change them.' No data is changed. | G18: Pass | H18: Reviewer: {'can_view': True, 'controls': {'Edit': 0, 'Activate': 0, 'Pause': 0, 'Close': 0, 'Delete engagement': 0}, 'edit_url': '/engagements/34853da2-870a-48c1-b9e8-941499be75f6/edit', 'save_msg': ['Your role can view engagements but not change them.'], 'save_http': [403, 403, 403, 403], 'api': {'patch': 403, 'status': 403, 'del': 403}}; Read only: {'can_view': True, 'controls': {'Edit': 0, 'Activate': 0, 'Pause': 0, 'Close': 0, 'Delete engagement': 0}, 'edit_url': '/engagements/34853da2-870a-48c1-b9e8-941499be75f6/edit', 'save_msg': ['Your role can view engagements but not change them.'], 'save_http': [403, 403, 403, 403, 403, 403, 403, 403], 'api': {'patch': 403, 'status': 403, 'del': 403}}. Both can VIEW the engagement but every mutating control is absent, and the API refuses PATCH / status / DELETE with 403. Engagement unchanged afterwards (no injected name present=True, status still Closed). Evidence: docs/uat-evidence/04-engagements/ | I18: Claude Code (Playwright, headed Chromium) | J18: 2026-08-03

Sheet 05. Scope
A1: Scope Definition
A2: Allow/deny scope items, matcher validation, and RBAC.
A4: Test ID | B4: Test Case | C4: Preconditions | D4: Test Steps (perform in order) | E4: Test Data | F4: Expected Result | G4: Status | H4: Actual Result / Notes | I4: Tested By | J4: Date
A5: SCOPE-01 | B5: Scope editor layout | C5: On an engagement detail. | D5: 1. Find the 'Scope' card. | E5: - | F5: Two lists: 'In scope (allow)' and 'Out of scope (deny — always wins)', each with an empty-state message when empty, plus an Add form below. | G5: Pass | H5: Fresh Draft engagement 'UAT M5 Scope & ROE' (e98bae34-1b5b-46fc-9368-9dcd10afd3f5) created for this module so both lists start empty. The Scope card renders exactly two headed lists in DOM order — 'In scope (allow)' then 'Out of scope (deny — always wins)' — each showing its empty state ('No allow rules — nothing is in scope yet.' / 'No deny rules.'), with the Add form below them (DOM-order assertion returned true). Evidence: docs/uat-evidence/05-scope-roe/SCOPE-01-empty-state.png | I5: Claude Code (Playwright, headed Chromium) | J5: 2026-08-04
A6: SCOPE-02 | B6: Add an allow URL | C6: Scope card, as admin/tester. | D6: 1. List = Allow. 2. Matcher type = URL. 3. Value = https://portal.example.com . 4. Add optional notes. 5. Click 'Add scope item'. | E6: https://portal.example.com | F6: The item appears under 'In scope (allow)' with its value, matcher label and notes. Value & Notes fields clear but List & Matcher stay selected for fast entry. | G6: Pass | H6: List=Allow, Matcher=URL, Value=https://portal.example.com, Notes='Primary customer portal — in scope for UAT', clicked 'Add scope item'. Item appeared under 'In scope (allow)' rendered as value + matcher label 'URL' + ' — ' + notes. Post-submit field state read from the DOM: value='' notes='' but kind='allow' matcher='url' retained, i.e. Value/Notes clear while List/Matcher stay selected for fast entry. Audit row scope.item_added/success logged for the admin. Evidence: docs/uat-evidence/05-scope-roe/SCOPE-02-allow-url-added.png | I6: Claude Code (Playwright, headed Chromium) | J6: 2026-08-04
A7: SCOPE-03 | B7: Add a deny rule | C7: Scope card. | D7: 1. List = Deny. 2. Add a value (e.g. domain admin.example.com). 3. Add. | E7: admin.example.com (deny) | F7: The item appears under 'Out of scope (deny — always wins)'. | G7: Pass | H7: List=Deny, Matcher=Domain, Value=admin.example.com, Notes='Admin plane excluded by client'. Item appeared under 'Out of scope (deny — always wins)' and NOT under the allow list; the allow list was unchanged. Selects still read kind='deny' matcher='domain' after the add. Evidence: docs/uat-evidence/05-scope-roe/SCOPE-03-deny-added.png | I7: Claude Code (Playwright, headed Chromium) | J7: 2026-08-04
A8: SCOPE-04 | B8: Matcher validation per type | C8: Scope card. | D8: 1. For each matcher type add a VALID then an INVALID value: URL: https://a.com vs not-a-url Domain: *.example.com vs bad_domain! IP/CIDR: 10.0.0.0/24 vs 999.1.1.1 API base: https://api.x/v1 vs ftp://x Repository: git@github.com:o/r.git vs random text | E8: see steps | F8: Valid values are accepted and normalized (lowercased / canonical CIDR). Invalid values are rejected with 'The value is not a valid {type} matcher.' | G8: Pass | H8: All ten documented cases driven through the real form. VALID all accepted: url https://a.com; domain *.example.com; ip_cidr 10.0.0.0/24; api_base https://api.x/v1; repo git@github.com:o/r.git. INVALID all rejected inline with the exact expected wording — 'The value is not a valid URL matcher.' (not-a-url), '…valid Domain matcher.' (bad_domain!), '…valid IP / CIDR matcher.' (999.1.1.1), '…valid API base matcher.' (ftp://x), '…valid Repository matcher.' (random text) — and no item was added in any rejected case. Normalization verified with extra probes: domain '*.MixedCase.EXAMPLE.com' stored as '*.mixedcase.example.com' (lowercased) and ip_cidr '10.44.55.66/24' stored as '10.44.55.0/24' (canonical network). Note on the parenthetical: url/api_base/repo values are deliberately stored VERBATIM (case preserved) because URL paths are case-significant; case-insensitivity is applied at enforcement instead — app/core/scope.py:175-182 lowercases scheme and hostname before comparing — so 'HTTPS://Upper.Example.COM/Path' as an allow rule still matches the lowercase target. Not a defect. Evidence: docs/uat-evidence/05-scope-roe/SCOPE-04-normalization.png | I8: Claude Code (Playwright, headed Chromium) | J8: 2026-08-04
A9: SCOPE-05 | B9: Remove a scope item | C9: At least one scope item. | D9: 1. Click 'Remove' next to an item. | E9: - | F9: The item disappears from its list immediately. | G9: Pass | H9: Clicked Remove next to 'HTTPS://Upper.Example.COM/Path'. The row disappeared from 'In scope (allow)' without a page reload (li count 9 -> 8) and stayed gone after router.refresh(); audit row scope.item_removed/success logged with the removed value. Two further removals in later steps behaved identically. Evidence: docs/uat-evidence/05-scope-roe/SCOPE-05-after-remove.png | I9: Claude Code (Playwright, headed Chromium) | J9: 2026-08-04
A10: SCOPE-06 | B10: Editing scope forces ROE re-acceptance | C10: ROE already accepted (see ROE-04). | D10: 1. Add or remove a scope item. 2. Look at the ROE panel. | E10: - | F10: The ROE status flips from 'Accepted' back to 'Acceptance required' — because scope changes the ROE content hash. Scans are blocked until re-accepted. | G10: Pass | H10: ROE accepted first (ROE-04), badge green 'Accepted', content hash b4f76d74…. Added allow item domain staging.example.com. Without leaving the page the ROE panel flipped to the amber 'Acceptance required' badge, the content hash changed to 6f912051… (SHA-256 covers the scope snapshot), the acknowledgement checkbox and Accept button re-appeared, and the new item showed inside the rendered ROE text. Removing an item drifts the hash the same way (verified in ROE-05) and reverts it to the original hash. The 'scans are blocked' half is the ROEStale guard in authorize_operation (app/core/scope.py:404-406, current_hash != roe_ack.content_hash) — the engagement is Draft here so scan blocking itself is exercised in module 10 (Safety), not verified through the UI in this row. Evidence: docs/uat-evidence/05-scope-roe/SCOPE-06-roe-reacceptance-required.png | I10: Claude Code (Playwright, headed Chromium) | J10: 2026-08-04
